Application has thrown an uncaught exception and is terminated:
Error: failed to connect to [localhost:27017]
    at Server.connect.connectionPool.on.server._serverState (\\10.207.188.48\volume-22-default\b6e1596fdce18f78aadb\eb3fb43bd98e49bd92d5e543ca052dcc\site\wwwroot\node_modules\mongodb\lib\mongodb\connection\server.js:564:74)
    at EventEmitter.emit (events.js:115:20)
    at connection.on._self._poolState (\\10.207.188.48\volume-22-default\b6e1596fdce18f78aadb\eb3fb43bd98e49bd92d5e543ca052dcc\site\wwwroot\node_modules\mongodb\lib\mongodb\connection\connection_pool.js:124:15)
    at EventEmitter.emit (events.js:91:17)
    at Socket.errorHandler (\\10.207.188.48\volume-22-default\b6e1596fdce18f78aadb\eb3fb43bd98e49bd92d5e543ca052dcc\site\wwwroot\node_modules\mongodb\lib\mongodb\connection\connection.js:465:10)
    at Socket.EventEmitter.emit (events.js:88:17)
    at Socket._destroy.self.errorEmitted (net.js:329:14)
    at process.startup.processNextTick.process._tickCallback (node.js:244:9)
